[2024-05-30T03:38:05.999+0000] {task_context_logger.py:104} WARNING - Marking task instance <TaskInstance: my_dag.task1 scheduled__2024-05-10T16:53:00+00:00 [queued]> stuck in queued as failed. If the task instance has available retries, it will be retried.
[2024-05-30T03:38:06.870+0000] {task_context_logger.py:104} ERROR - Executor reports task instance <TaskInstance: my_dag.task1 scheduled__2024-05-10T16:53:00+00:00 [queued]> finished (failed) although the task says it's queued. (Info: None) Was the task killed externally?
