[2024-05-30T03:13:36.275+0000] {task_context_logger.py:104} ERROR - Executor reports task instance <TaskInstance: my_dag.task1 scheduled__2024-05-22T16:53:00+00:00 [queued]> finished (failed) although the task says it's queued. (Info: None) Was the task killed externally?
